Traceback (most recent call last):
  File "/home/lyngsberg/miniconda3/envs/fagprojekt/lib/python3.13/site-packages/wandb/sdk/wandb_config.py", line 165, in __getattr__
    return self.__getitem__(key)
           ~~~~~~~~~~~~~~~~^^^^^
  File "/home/lyngsberg/miniconda3/envs/fagprojekt/lib/python3.13/site-packages/wandb/sdk/wandb_config.py", line 130, in __getitem__
    return self._items[key]
           ~~~~~~~~~~~^^^^^
KeyError: 'optimizer_name'
The above exception was the direct cause of the following exception:
Traceback (most recent call last):
  File "/home/lyngsberg/fagproject/02466_project/fagproject/src/project/sweep_train.py", line 185, in <module>
    train_model()
    ~~~~~~~~~~~^^
  File "/home/lyngsberg/fagproject/02466_project/fagproject/src/project/sweep_train.py", line 30, in train_model
    optimizer_name = config.optimizer_name
                     ^^^^^^^^^^^^^^^^^^^^^
  File "/home/lyngsberg/miniconda3/envs/fagprojekt/lib/python3.13/site-packages/wandb/sdk/wandb_config.py", line 167, in __getattr__
    raise AttributeError(
        f"{self.__class__!r} object has no attribute {key!r}"
    ) from ke
AttributeError: <class 'wandb.sdk.wandb_config.Config'> object has no attribute 'optimizer_name'